<?xml version="1.0" encoding="utf-8"?>
<robot xmlns:xacro="http://www.ros.org/wiki/xacro"
       name="leo">

  <xacro:arg name="default_antenna" default="true"/>
  
  <!-- MACROS -->

  <xacro:macro name="rocker_link" params="name">
    <link name="rocker_${name}_link">
    <inertial>
      <mass value="1.387336"/>
      <origin xyz="0 0.01346 -0.06506"/>
      <inertia ixx="0.002956" ixy="-0.000001489324" ixz="-0.000008103407" iyy="0.02924" iyz="0.00007112" izz="0.02832"/>
    </inertial>
      <visual>
        <geometry>
          <mesh filename="package://leo_description/models/Rocker.dae"/>
        </geometry>
      </visual>
      <collision>
        <geometry>
          <mesh filename="package://leo_description/models/Rocker.dae"/>
        </geometry>
      </collision>
    </link>
  </xacro:macro>

  <xacro:macro name="wheel_link" params="name model"> 
    <link name="wheel_${name}_link">
      <inertial>
        <mass value="0.283642"/>
        <origin xyz="0 0.030026 0"/>
        <inertia ixx="0.000391" ixy="0.00000123962" ixz="5.52582e-7" iyy="0.0004716" iyz="-0.000002082042" izz="0.000391"/>
      </inertial>
      <visual>
        <geometry>
          <mesh filename="package://leo_description/models/Wheel${model}.dae"/>
        </geometry>
      </visual>
      <collision>
        <origin xyz="0 0.04485 0" rpy="${pi/2} 0 0"/>
        <geometry>
          <cylinder radius="0.06" length="0.07"/>
        </geometry>
      </collision>
    </link>
  </xacro:macro>

  <!-- LINKS -->

  <link name="base_link">
    <inertial>
      <mass value="1.584994"/>
      <origin xyz="-0.019662 0.011643 -0.031802"/>
      <inertia ixx="0.01042" ixy="0.001177" ixz="-0.0008871" iyy="0.01045" iyz="0.0002226" izz="0.01817"/>
    </inertial>
    <visual>
      <geometry>
        <mesh filename="package://leo_description/models/Chassis.dae"/>
      </geometry>
    </visual>
    <collision>
      <geometry>
        <mesh filename="package://leo_description/models/Chassis.dae"/>
      </geometry>
    </collision>
  </link>

  <xacro:rocker_link name="L"/>
  <xacro:rocker_link name="R"/>
  <xacro:wheel_link name="FL" model="A"/>
  <xacro:wheel_link name="RL" model="A"/>
  <xacro:wheel_link name="FR" model="B"/>
  <xacro:wheel_link name="RR" model="B"/>

  <xacro:if value="$(arg default_antenna)">
    <link name="antenna_link">
      <inertial>
        <mass value="0.001237"/>
        <origin xyz="0 0 0.028828"/>
        <inertia ixx="2.5529e-7" ixy="0.0" ixz="0.0" iyy="2.5529e-7" iyz="0.0" izz="1.354e-8"/>
      </inertial>
      <visual>
        <geometry>
          <mesh filename="package://leo_description/models/Antenna.dae"/>
        </geometry>
      </visual>
      <collision>
        <origin xyz="0 0 0.028"/>
        <geometry>
          <cylinder radius="0.0055" length="0.056"/>
        </geometry>
      </collision>
    </link>
  </xacro:if>

  <link name="camera_frame"/>

  <!-- JOINTS -->

  <joint name="rocker_L_joint" type="revolute">
    <origin xyz="0.00263 0.14167 -0.04731" rpy="0 0 ${pi}"/>
    <parent link="base_link"/>
    <child link="rocker_L_link"/>
    <axis xyz="0 1 0"/>
    <limit effort="10" lower="-0.24" upper="0.24" velocity="0.5"/> <!-- TODO -->
  </joint>

  <joint name="rocker_R_joint" type="revolute">
    <origin xyz="0.00263 -0.14167 -0.04731" rpy="0 0 0"/>
    <parent link="base_link"/>
    <child link="rocker_R_link"/>
    <axis xyz="0 1 0"/>
    <limit effort="10" lower="-0.24" upper="0.24" velocity="0.5"/> <!-- TODO -->
    <mimic joint="rocker_L_joint"/>
  </joint>

  <joint name="wheel_FL_joint" type="continuous">
    <origin xyz="-0.15256 -0.08214 -0.08802" rpy="0 0 0"/>
    <parent link="rocker_L_link"/>
    <child link="wheel_FL_link"/>
    <axis xyz="0 -1 0"/>
    <limit effort="10" velocity="6.0"/> <!-- TODO -->
  </joint>

  <joint name="wheel_RL_joint" type="continuous">
    <origin xyz="0.15256 -0.08214 -0.08802" rpy="0 0 0"/>
    <parent link="rocker_L_link"/>
    <child link="wheel_RL_link"/>
    <axis xyz="0 -1 0"/>
    <limit effort="10" velocity="6.0"/> <!-- TODO -->
  </joint>

  <joint name="wheel_FR_joint" type="continuous">
    <origin xyz="0.15256 -0.08214 -0.08802" rpy="0 0 0"/>
    <parent link="rocker_R_link"/>
    <child link="wheel_FR_link"/>
    <axis xyz="0 1 0"/>
    <limit effort="10" velocity="6.0"/> <!-- TODO -->
  </joint>

  <joint name="wheel_RR_joint" type="continuous">
    <origin xyz="-0.15256 -0.08214 -0.08802" rpy="0 0 0"/>
    <parent link="rocker_R_link"/>
    <child link="wheel_RR_link"/>
    <axis xyz="0 1 0"/>
    <limit effort="10" velocity="6.0"/> <!-- TODO -->
  </joint>

  <xacro:if value="$(arg default_antenna)">
    <joint name="antenna_joint" type="fixed">
        <origin xyz="-0.0052 0.056 -0.0065" rpy="0 0 0"/>
        <parent link="base_link"/>
        <child link="antenna_link"/>
    </joint>
  </xacro:if>

  <joint name="camera_joint" type="fixed">
      <origin xyz="0.0971 0 -0.0427" rpy="${-pi/2 - 0.2094} 0 ${-pi/2}"/>
      <parent link="base_link"/>
      <child link="camera_frame"/>
  </joint>

</robot>