<?xml version="1.0" encoding="utf-8"?>
<!-- This URDF was automatically created by SolidWorks to URDF Exporter! Originally created by Stephen Brawner (brawner@gmail.com) 
     Commit Version: 1.5.0-0-g9aa0fdb  Build Version: 1.5.7004.21443
     For more information, please see http://wiki.ros.org/sw_urdf_exporter -->
<robot
  name="leo_description">
  <link
    name="base_link">
    <inertial>
      <origin
        xyz="-0.00722738025166191 -0.0157342555876152 -0.0514386362523208"
        rpy="0 0 0" />
      <mass
        value="1.18333842438659" />
      <inertia
        ixx="0.00220253251903183"
        ixy="-3.11789791908521E-06"
        ixz="1.84372634491565E-06"
        iyy="0.00186758959999937"
        iyz="1.31248202136285E-05"
        izz="0.00326780636889239" />
    </inertial>
    <visual>
      <origin
        xyz="0 0 0"
        rpy="0 0 0" />
      <geometry>
        <mesh
          filename="package://leo_description/meshes/base_link.STL" />
      </geometry>
      <material
        name="base">
        <color
          rgba="0.752941176470588 0.752941176470588 0.752941176470588 1" />
      </material>
    </visual>
    <collision>
      <origin
        xyz="0 0 0"
        rpy="0 0 0" />
      <geometry>
        <mesh
          filename="package://leo_description/meshes/base_link.STL" />
      </geometry>
    </collision>
  </link>
  <link
    name="wheel_FL_link">
    <inertial>
      <origin
        xyz="-4.43698912840074E-06 -4.6985892357132E-06 0.00391651753147765"
        rpy="0 0 0" />
      <mass
        value="0.162812028045966" />
      <inertia
        ixx="0.00024573710371291"
        ixy="4.33843425943982E-09"
        ixz="5.46698222888878E-11"
        iyy="0.000245736463236059"
        iyz="2.76826955254868E-09"
        izz="0.000387997815645929" />
    </inertial>
    <visual>
      <origin
        xyz="0 0 0"
        rpy="0 0 0" />
      <geometry>
        <mesh
          filename="package://leo_description/meshes/wheel_FL_link.STL" />
      </geometry>
      <material
        name="wheel">
        <color
          rgba="0.752941176470588 0.752941176470588 0.752941176470588 1" />
      </material>
    </visual>
    <collision>
      <origin
        xyz="0 0 0"
        rpy="0 0 0" />
      <geometry>
        <mesh
          filename="package://leo_description/meshes/wheel_FL_link.STL" />
      </geometry>
    </collision>
  </link>
  <joint
    name="wheel_FL_joint"
    type="continuous">
    <origin
      xyz="-0.16833 0.14211 -0.13136"
      rpy="1.5708 -0.28705 1.5708" />
    <parent
      link="base_link" />
    <child
      link="wheel_FL_link" />
    <axis
      xyz="0 0 1" />
    <safety_controller
      k_velocity="0" />
  </joint>
  <link
    name="wheel_RL_link">
    <inertial>
      <origin
        xyz="-4.43698914094626E-06 -4.69858915372323E-06 0.00391651753148009"
        rpy="0 0 0" />
      <mass
        value="0.162812028045961" />
      <inertia
        ixx="0.000245737103712841"
        ixy="4.33843427093914E-09"
        ixz="5.4672421588949E-11"
        iyy="0.000245736463236041"
        iyz="2.76826957278371E-09"
        izz="0.000387997815645841" />
    </inertial>
    <visual>
      <origin
        xyz="0 0 0"
        rpy="0 0 0" />
      <geometry>
        <mesh
          filename="package://leo_description/meshes/wheel_RL_link.STL" />
      </geometry>
      <material
        name="wheel">
        <color
          rgba="0.752941176470588 0.752941176470588 0.752941176470588 1" />
      </material>
    </visual>
    <collision>
      <origin
        xyz="0 0 0"
        rpy="0 0 0" />
      <geometry>
        <mesh
          filename="package://leo_description/meshes/wheel_RL_link.STL" />
      </geometry>
    </collision>
  </link>
  <joint
    name="wheel_RL_joint"
    type="continuous">
    <origin
      xyz="-0.16833 -0.14704 -0.1312"
      rpy="1.5708 0.29774 1.5708" />
    <parent
      link="base_link" />
    <child
      link="wheel_RL_link" />
    <axis
      xyz="0 0 1" />
    <safety_controller
      k_velocity="0" />
  </joint>
  <link
    name="wheel_FR_link">
    <inertial>
      <origin
        xyz="6.01916131054425E-06 1.71290029617188E-06 0.00606817838270973"
        rpy="0 0 0" />
      <mass
        value="0.162812028045959" />
      <inertia
        ixx="0.000245740869276952"
        ixy="2.42238914491884E-09"
        ixz="4.71342130464578E-11"
        iyy="0.000245732697671881"
        iyz="2.7805675384073E-09"
        izz="0.000387997815645827" />
    </inertial>
    <visual>
      <origin
        xyz="0 0 0"
        rpy="0 0 0" />
      <geometry>
        <mesh
          filename="package://leo_description/meshes/wheel_FR_link.STL" />
      </geometry>
      <material
        name="wheel">
        <color
          rgba="0.752941176470588 0.752941176470588 0.752941176470588 1" />
      </material>
    </visual>
    <collision>
      <origin
        xyz="0 0 0"
        rpy="0 0 0" />
      <geometry>
        <mesh
          filename="package://leo_description/meshes/wheel_FR_link.STL" />
      </geometry>
    </collision>
  </link>
  <joint
    name="wheel_FR_joint"
    type="continuous">
    <origin
      xyz="0.16026 0.14211 -0.13136"
      rpy="1.5708 0.80343 1.5708" />
    <parent
      link="base_link" />
    <child
      link="wheel_FR_link" />
    <axis
      xyz="0 0 1" />
    <safety_controller
      k_velocity="0" />
  </joint>
  <link
    name="wheel_RR_link">
    <inertial>
      <origin
        xyz="6.01916147048576E-06 1.71290010028691E-06 0.006068178382686"
        rpy="0 0 0" />
      <mass
        value="0.162812028046661" />
      <inertia
        ixx="0.000245740869278297"
        ixy="2.42238971859393E-09"
        ixz="4.71354760058098E-11"
        iyy="0.000245732697672163"
        iyz="2.78056967904515E-09"
        izz="0.000387997815647396" />
    </inertial>
    <visual>
      <origin
        xyz="0 0 0"
        rpy="0 0 0" />
      <geometry>
        <mesh
          filename="package://leo_description/meshes/wheel_RR_link.STL" />
      </geometry>
      <material
        name="">
        <color
          rgba="0.752941176470588 0.752941176470588 0.752941176470588 1" />
      </material>
    </visual>
    <collision>
      <origin
        xyz="0 0 0"
        rpy="0 0 0" />
      <geometry>
        <mesh
          filename="package://leo_description/meshes/wheel_RR_link.STL" />
      </geometry>
    </collision>
  </link>
  <joint
    name="wheel_RR_joint"
    type="continuous">
    <origin
      xyz="0.16026 -0.14704 -0.1312"
      rpy="1.5708 1.3882 1.5708" />
    <parent
      link="base_link" />
    <child
      link="wheel_RR_link" />
    <axis
      xyz="0 0 1" />
    <safety_controller
      k_velocity="0" />
  </joint>
</robot>